Workbook
Name \a: [1]CPK!$Y$1:$Z$2
Name __A1: #N/A
Name __hdd1: #REF!
Name __Q3: [6]YSS31!#REF!
Name __stv1: [7]DataIn!$P$9
Name _1: #REF!
Name _10._Sensitive_Customer_Information_?__Y_N: [8]InformationAssetInventory!#REF!
Name _2: #REF!
Name _3: #REF!
Name _５８期: #REF!
Name _５９期: #REF!
Name _６０期: #REF!
Name _６１期: #REF!
Name _６２期: #REF!
Name _６３期: #REF!
Name _６４期: #REF!
Name _６５期: #REF!
Name _６６期: #REF!
Name _６７期: #REF!
Name _６８期: #REF!
Name _６９期: #REF!
Name _７０期: #REF!
Name _７１期: #REF!
Name _７２期: #REF!
Name _７３期: #REF!
Name _A1: #N/A
Name _hdd1: #REF!
Name _Ｍ１: #REF!
Name _Ｍ２: #REF!
Name _Ｍ３: #REF!
Name _Q3: [10]YSS31!#REF!
Name _stv1: [7]DataIn!$P$9
Name A: #N/A
Name ａａ: #REF!
Name aaa: [11]受注台帳!#REF!
Name Adua: #REF!
Name AI: #N/A
Name AIR: #REF!
Name and: [12]総合価格!$B$565:$K$673
Name asd: #N/A
Name atas3sigma: #REF!
Name AVG: [7]DataIn!$P$7
Name AVG_B: [13]DataInB!$P$7
Name B: #REF!
Name batasbawahx: #REF!
Name bawah3sigma: #REF!
Name bb: #REF!
Name bbb: [11]受注台帳!#REF!
Name BRCONC: #REF!
Name BRCONCJUDGE: #REF!
Name BRCOUNT: #REF!
Name BRCOUNTERROR: #REF!
Name BRERROR: #REF!
Name BRERRORJUDGE: #REF!
Name C.point: #REF!
Name C_1_CURRENT: #REF!
Name C_1_DEADTIME: #REF!
Name C_1_EFFECTIVETIME: #REF!
Name C_1_FILTER: #REF!
Name C_1_MEASTIME: #REF!

Sheet AUDIT KMC
D1: LIST CONTROL PC | U1: INFORMASI PEMBELIAN
A2: UPDATE | D2: : NOVEMBER 2025
A3: User | I3: IP ADDRESS MAIN | J3: IP ADDRESS BACKUP | K3: Tahun | N3: Status | O3: KLASIFIKASI | P3: LISENSI
A4: NO | B4: NO.ASSET | C4: TYPE | D4: DIVISI | E4: DEPT | F4: NAMA | G4: NIK | H4: HOSTNAME | K4: Pembelian | L4: Batas Depresiasi (5 Tahun) | M4: Batas Extend (+1 Tahun) | P4: 2025 | Q4: 2026 | R4: 2027 | S4: Trend Micro (Max PC & Svr 265) | T4: Cybereason (Max PC & Svr 245) | U4: SUPPLIER | V4: NO PO | W4: TGL AKUISISI | X4: PIC SUPPLIER | Y4: KONTAK SUPPLIER
A5: 1 | B5: FI-00936 | C5: LAPTOP | D5: EXECUTIVE BOARD | E5: - | F5: KANTO SHIBATANI (X1 Carbon) | G5: 110501 | H5: PIK1COM049 | I5: 172.17.12.19 | J5: DHCP | K5: 2024 | L5: 2029 | M5: 2030 | N5: Active | O5: LAPTOP MANAGERIAL | P5: E3 INTUNE | Q5: E3 INTUNE | R5: E3 INTUNE | S5: 1 | T5: 1
A6: 2 | B6: FI-00639 | C6: LAPTOP | D6: EXECUTIVE BOARD | E6: - | F6: MUTSUHIKO UCHIYAMA | G6: 1007001 | H6: PIKPC116 | I6: 172.17.12.16 | J6: DHCP | K6: 2021 | L6: 2026 | M6: 2027 | N6: Active | O6: LAPTOP MANAGERIAL | P6: E3 INTUNE | Q6: E3 INTUNE | R6: E3 INTUNE | S6: 1 | T6: 1 | Z6: OFFICER ADMIN | AA6: OHB | AB6: OHB | AC6: OHB | AD6: OHB
A7: 3 | B7: FI-00640 | C7: LAPTOP | D7: EXECUTIVE BOARD | E7: - | F7: SHIBATANI KANTO | G7: 110501 | H7: PIKPC106 | I7: 172.17.12.18 | J7: DHCP | K7: 2021 | L7: 2026 | M7: 2027 | N7: Active | O7: LAPTOP MANAGERIAL | P7: E3 INTUNE | Q7: E3 INTUNE | R7: E3 INTUNE | S7: 1 | T7: 1 | Z7: TEKNIKAL | AA7: OHB | AB7: OHB | AC7: OHB | AD7: OHB
A8: 4 | B8: FI-00641 | C8: LAPTOP | D8: EXECUTIVE BOARD | E8: - | F8: ERMA PURNAMA WIDA PANE | G8: 1008001 | H8: PIKPC107 | I8: 172.17.12.31 | J8: DHCP | K8: 2021 | L8: 2026 | M8: 2027 | N8: Active | O8: LAPTOP MANAGERIAL | P8: E3 INTUNE | Q8: E3 INTUNE | R8: E3 INTUNE | S8: 1 | T8: 1 | Z8: OPERATOR | AA8: OHB | AB8: OHB | AC8: OHB | AD8: OHB
A9: 5 | B9: FI-01114 | C9: ALL IN ONE | D9: FINANCE DIV | E9: FA | F9: MAUDICA FAMELA AGISTY PUTERI | G9: 2508023 | H9: PIK1COM160 | I9: 172.17.12.192 | J9: 172.17.128.8 | K9: 2025 | L9: 2030 | M9: 2031 | N9: Active | O9: OFFICER ADMIN | P9: OHB | Q9: - | R9: - | S9: 1 | T9: 1 | U9: SBTELECOM | V9: 023/PO/HR&GA/GA/VII/2025 | X9: ASTRI | Y9: 0811-1067-925
A10: 6 | B10: FI-01115 | C10: ALL IN ONE | D10: FINANCE DIV | E10: FA | F10: DEVARA RADITYA FAJRIAWAN | G10: 2203039 | H10: PIK1COM161 | I10: 172.17.12.197 | J10: 172.17.128.7 | K10: 2025 | L10: 2030 | M10: 2031 | N10: Active | O10: OFFICER ADMIN | P10: OHB | Q10: - | R10: - | S10: 1 | T10: 1 | U10: SBTELECOM | V10: 023/PO/HR&GA/GA/VII/2025 | X10: ASTRI | Y10: 0811-1067-925
A11: 7 | B11: FI-01026 | C11: ALL IN ONE | D11: FINANCE DIV | E11: FA | F11: ASTIANI PEBRIANA | G11: 2203040 | H11: PIK1COM120 | I11: 172.17.12.199 | J11: 172.17.128.6 | K11: 2024 | L11: 2029 | M11: 2030 | N11: Active | O11: OFFICER ADMIN | P11: OHB Apr | Q11: - | R11: - | S11: 1 | T11: 1 | U11: TETRANET | V11: 039/PO/HR&GA/GA/X/2024 | W11: 1 Dec 2024 | X11: AFDAL | Z11: APLIKASI WMS | AA11: OHB | AB11: OHB | AC11: OHB | AD11: OHB
A12: 8 | B12: FI-00767 | C12: LAPTOP | D12: FINANCE DIV | E12: FA | F12: YAYAH ROHIYAH | G12: 1307002 | H12: PIK1COM023 | I12: 172.17.12.189 | J12: DHCP | K12: 2023 | L12: 2028 | M12: 2029 | N12: Active | O12: LAPTOP MANAGERIAL | P12: E3 | Q12: E3 | R12: E3 | S12: 1 | T12: 1
A13: 9 | B13: FI-00775 | C13: ALL IN ONE | D13: FINANCE DIV | E13: FA | F13: FANI YULIANI | G13: 1505006 | H13: PIK1COM016 | I13: 172.17.12.191 | J13: 172.17.128.5 | K13: 2023 | L13: 2028 | M13: 2029 | N13: Active | O13: OFFICER ADMIN | P13: OHB Apr | Q13: - | R13: - | S13: 1 | T13: 1
A14: 10 | B14: FI-00927 | C14: ALL IN ONE | D14: FINANCE DIV | E14: FA | F14: FERA PEBRIANA | G14: 1403005 | H14: PIK1COM044 | I14: 172.17.12.190 | J14: 172.17.128.4 | K14: 2023 | L14: 2028 | M14: 2029 | N14: Active | O14: OFFICER ADMIN | P14: OHB Apr | Q14: - | R14: - | S14: 1 | T14: 1
A15: 11 | B15: FI-00670 | C15: ALL IN ONE | D15: FINANCE DIV | E15: FA | F15: STEVE FANNIE | G15: 1011032 | H15: PIKPC132 | I15: 172.17.12.188 | J15: 172.17.128.3 | K15: 2022 | L15: 2027 | M15: 2028 | N15: Active | O15: AKTIVITAS KHUSUS | P15: AFB | Q15: AFB Jul | R15: AFB Jul | S15: 1 | T15: 1
A16: 12 | B16: FI-00607 | C16: LAPTOP | D16: FINANCE DIV | E16: FA | F16: IMAN KOESTIAMAN | G16: 1112021 | H16: PIKLT004 | I16: 172.17.12.186 | J16: DHCP | K16: 2021 | L16: 2026 | M16: 2027 | N16: Active | O16: LAPTOP MANAGERIAL | P16: E3 INTUNE | Q16: E3 Jun | R16: E3 Jun | S16: 1 | T16: 1
A17: 13 | B17: FI-01104 | C17: ALL IN ONE | D17: GENERAL AFFAIR DIV | E17: HRGA | F17: ASHRI DANIELLI | G17: 1402007 | H17: PIK1COM149 | I17: 172.17.12.76 | J17: 172.17.128.27 | K17: 2025 | L17: 2030 | M17: 2031 | N17: Active | O17: OPERATOR | P17: OHB | Q17: - | R17: - | S17: 1 | T17: 1 | U17: SBTELECOM | V17: 032/PO/HR&GA/GA/VI/2025 | W17: 1 Sep 2025 | X17: ASTRI | Y17: 0811-1067-925
A18: 14 | B18: FI-01094 | C18: LAPTOP | D18: GENERAL AFFAIR DIV | E18: HR GA | F18: PAYROLL (AYUNG YUANSAH) | G18: 1205001 | H18: PIK1COM152 | I18: 172.17.12.37 | J18: DHCP | K18: 2025 | L18: 2030 | M18: 2031 | N18: Active | O18: LAPTOP MANAGERIAL | P18: E3 | Q18: E3 | R18: E3 | S18: 1 | T18: 1 | U18: SBTELECOM | V18: 034/PO/HR&GA/GA/VI/2025 | W18: 1 Sep 2025 | X18: ASTRI | Y18: 0811-1067-925
A19: 15 | B19: FI-01019 | C19: ALL IN ONE | D19: GENERAL AFFAIR DIV | E19: HR GA | F19: WINCI AYU ADIANINGSIH | G19: 2412014 | H19: PIK1COM109 | I19: 172.17.12.75 | J19: 172.17.128.14 | K19: 2024 | L19: 2029 | M19: 2030 | N19: Active | O19: OFFICER ADMIN | P19: OHB Apr | Q19: - | R19: - | S19: 1 | T19: 1 | U19: TETRANET | V19: 009/PO/HR&GA/GA/X/2024 | W19: 45627 | X19: AFDAL
A20: 16 | B20: FI-01004 | C20: ALL IN ONE | D20: GENERAL AFFAIR DIV | E20: HR GA | F20: ANDRI FAISAL | G20: 1411001 | H20: PIK1COM102 | I20: 172.17.12.45 | J20: 172.17.128.12 | K20: 2024 | L20: 2029 | M20: 2030 | N20: Active | O20: OFFICER ADMIN | P20: OHB Apr | Q20: - | R20: - | S20: 1 | T20: 1
A21: 17 | B21: FI-01003 | C21: ALL IN ONE | D21: GENERAL AFFAIR DIV | E21: HR GA | F21: AHMAD KAMALUDIN (EX: RATNA) | G21: 1604048 | H21: PIK1COM100 | I21: 172.17.12.54 | J21: 172.17.128.13 | K21: 2024 | L21: 2029 | M21: 2030 | N21: Active | O21: OFFICER ADMIN | P21: OHB Apr | Q21: - | R21: - | S21: 1 | T21: 1
A22: 18 | B22: FI-00981 | C22: ALL IN ONE | D22: GENERAL AFFAIR DIV | E22: HR GA | F22: ERNA YULIAWATI | G22: 1208059 | H22: PIK1COM084 | I22: 172.17.12.43 | J22: 172.17.128.11 | K22: 2024 | L22: 2029 | M22: 2030 | N22: Active | O22: OFFICER ADMIN | P22: OHB Apr | Q22: - | R22: - | S22: 1 | T22: 1
A23: 19 | B23: FI-00960 | C23: ALL IN ONE | D23: GENERAL AFFAIR DIV | E23: HR GA | F23: SUSINTAWATI (TC) | G23: 1208058 | H23: PIK1COM056 | I23: 172.17.12.47 | J23: 172.17.128.15 | K23: 2024 | L23: 2029 | M23: 2030 | N23: Active | O23: OFFICER ADMIN | P23: OHB Jun (PP16) | Q23: - | R23: - | S23: 1 | T23: 1
A24: 20 | B24: FI-00787 | C24: LAPTOP | D24: GENERAL AFFAIR DIV | E24: HR GA | F24: TC (AYUNG) | G24: 1205001 | H24: PIK1COM035 | I24: 172.17.12.48 | J24: DHCP | K24: 2023 | L24: 2028 | M24: 2029 | N24: Active | O24: LAPTOP MANAGERIAL | P24: E3 | Q24: E3 | R24: E3 | S24: 1 | T24: 1
A25: 21 | B25: FI-00660 | C25: ALL IN ONE | D25: GENERAL AFFAIR DIV | E25: HR GA | F25: ADNY AGESTIAN VIRZY | G25: 1605034 | H25: PIKPC122 | I25: 172.17.12.222 | J25: 172.17.128.16 | K25: 2022 | L25: 2027 | M25: 2028 | N25: Active | O25: OFFICER ADMIN | P25: OHB Apr | Q25: - | R25: - | S25: 1 | T25: 1 | U25: XDC | V25: 012/PO/HR&GA/GA/GA/III/2025 | W25: 45748 | X25: WIDI | Y25: 0821-2106-7715
A26: 22 | B26: FI-00762 | C26: LAPTOP | D26: GENERAL AFFAIR DIV | E26: HRGA | F26: RIA RATNANINGSIH | G26: 1605033 | H26: PIK1COM022 | I26: 172.17.12.71 | J26: DHCP | K26: 2023 | L26: 2028 | M26: 2029 | N26: Active | O26: LAPTOP MANAGERIAL | P26: E3 | Q26: E3 | R26: E3 | S26: 1 | T26: 1
A27: 23 | B27: FI-00654 | C27: LAPTOP | D27: GENERAL AFFAIR DIV | E27: HRGA | F27: KOITO M-14 (AYUNG YUANSAH) | G27: 1205001 | H27: PIKPC115 | I27: 172.17.12.214 | J27: DHCP | K27: 2021 | L27: 2026 | M27: 2027 | N27: Active | O27: LAPTOP MEETING | P27: E3 | Q27: E3 | R27: E3 | S27: 1 | T27: 1
A28: 24 | B28: FI-00603 | C28: MINI PC | D28: GENERAL AFFAIR DIV | E28: HRGA | F28: MEETING 14 (OJT) EX : SARI REZEKI | G28: 1205001 | H28: PIKPC141 | I28: - | J28: 172.17.128.17 | K28: 2021 | L28: 2026 | M28: 2027 | N28: Active Brrow | O28: MINI PC MEETING | P28: PP16 | S28: 1 | T28: 0
A29: 25 | B29: FI-00602 | C29: MINI PC | D29: GENERAL AFFAIR DIV | E29: HRGA | F29: ROOM TC DEV EX : DEPI JAELANI | G29: 1205001 | H29: PIKPC004 | I29: 172.17.12.215 | J29: 172.17.128.18 | K29: 2021 | L29: 2026 | M29: 2027 | N29: Active Brrow | O29: MINI PC MEETING | P29: PP16 | S29: 1 | T29: 0
A30: 26 | B30: FI-00601 | C30: MINI PC | D30: GENERAL AFFAIR DIV | E30: HRGA | F30: MEETING 12 (OJT) EX: WINDA | G30: 1205001 | H30: PIKPC003 | I30: - | J30: 172.17.128.19 | K30: 2021 | L30: 2026 | M30: 2027 | N30: Active Brrow | O30: MINI PC MEETING | P30: PP16 | S30: 1 | T30: 0
A31: 27 | B31: FI-00583 | C31: MINI PC | D31: GENERAL AFFAIR DIV | E31: HRGA | F31: ROOM MEETING 3 EX : YAHDI | G31: 1205001 | H31: PIKPC146 | I31: 172.17.11.212 | J31: 172.17.128.20 | K31: 2020 | L31: 2025 | M31: 2026 | N31: Active Brrow | O31: MINI PC MEETING | P31: PP16 | S31: 1 | T31: 0
A32: 28 | B32: FI-00582 | C32: MINI PC | D32: GENERAL AFFAIR DIV | E32: HRGA | F32: MEETING 10 (OJT) EX : NURHASIM | G32: 1205001 | H32: PIKPC149 | I32: - | J32: 172.17.118.2 | K32: 2020 | L32: 2025 | M32: 2026 | N32: Active Brrow | O32: MINI PC MEETING | P32: PP16 | S32: 1 | T32: 0
A33: 29 | B33: FI-00581 | C33: MINI PC | D33: GENERAL AFFAIR DIV | E33: HRGA | F33: MEETING 09 (OJT) EX: ABDUL WACHID | G33: 1205001 | H33: PURPC018 | I33: - | J33: 172.17.128.21 | K33: 2020 | L33: 2025 | M33: 2026 | N33: Active Brrow | O33: MINI PC MEETING | P33: PP16 | S33: 1 | T33: 0
A34: 30 | B34: FI-00576 | C34: MINI PC | D34: GENERAL AFFAIR DIV | E34: HRGA | F34: MEETING 08 EX: ADNY | G34: 1205001 | H34: HRGAPC025 | I34: - | J34: 172.17.128.22 | K34: 2020 | L34: 2025 | M34: 2026 | N34: Active Brrow | O34: MINI PC MEETING | P34: PP16 | S34: 1 | T34: 0
A35: 31 | B35: FI-00575 | C35: MINI PC | D35: GENERAL AFFAIR DIV | E35: HRGA | F35: MEETING 07 EX : MONITOR 2 | G35: 1205001 | H35: - | I35: - | J35: 172.17.128.23 | K35: 2020 | L35: 2025 | M35: 2026 | N35: Active Brrow | O35: MINI PC MEETING | P35: PP16 | S35: 1 | T35: 0
A36: 32 | B36: FI-00574 | C36: MINI PC | D36: GENERAL AFFAIR DIV | E36: HRGA | F36: ROOM MEETING A EX : RICHAR | G36: 1205001 | H36: INJPC003 | I36: 172.17.12.211 | J36: 172.17.128.24 | K36: 2020 | L36: 2025 | M36: 2026 | N36: Active Brrow | O36: MINI PC MEETING | P36: PP16 | S36: 1 | T36: 0
A37: 33 | B37: FI-00573 | C37: MINI PC | D37: GENERAL AFFAIR DIV | E37: HRGA | F37: MEETING 05 EX: TARNO | G37: 1205001 | H37: LOGPC003 | I37: - | J37: 172.17.118.3 | K37: 2020 | L37: 2025 | M37: 2026 | N37: Active Brrow | O37: MINI PC MEETING | P37: PP16 | S37: 1 | T37: 0
A38: 34 | B38: FI-00572 | C38: MINI PC | D38: GENERAL AFFAIR DIV | E38: HRGA | F38: ROOM MEETING 1 EX: FATIKA | G38: 1205001 | H38: QEPC021 | I38: 172.17.11.211 | J38: 172.17.118.4 | K38: 2020 | L38: 2025 | M38: 2026 | N38: Active Brrow | O38: MINI PC MEETING | P38: PP16 | S38: 1 | T38: 0
A39: 35 | B39: FI-00571 | C39: MINI PC | D39: GENERAL AFFAIR DIV | E39: HRGA | F39: MEETING 03 EX :IDHAM RAKHMADI | G39: 1205001 | H39: HRGAPC024 | I39: - | J39: 172.17.118.5 | K39: 2020 | L39: 2025 | M39: 2026 | N39: Active Brrow | O39: MINI PC MEETING | P39: PP16 | S39: 1 | T39: 0
... A41: 37 | B41: FI-00553 | C41: MINI PC | D41: GENERAL AFFAIR DIV | E41: HRGA | F41: ROOM MEETING 5 EX: AFIFAH SALMA | G41: 1205001 | H41: QEPC019 | I41: 172.17.11.215 | J41: 172.17.128.25 | K41: 2020 | L41: 2025 | M41: 2026 | N41: Active Brrow | O41: MINI PC MEETING | P41: PP16 | S41: 1 | T41: 0
...

Sheet SUMMARY LINK
A1: SUMARRY
A3: Type | C3: Lisensi : | E3: OS : | I3: NOTE :
A4: 1. PC | C4: OHB | D4: 136 | E4: Windows 10 | F4: 5 | I4: Standar PC | J4: 226
A5: - All In One | B5: 137 | C5: E3 | D5: 54 | E5: Windows 11 | F5: 224 | I5: Additional 2025 | J5: 3
A6: - Mini Pc | B6: 13 | C6: AFB | D6: 21 | E6: Total Windows | F6: 229 | I6: Total PC | J6: =SUM(J4:J5) -> 229
A7: - Workstation | B7: 15 | C7: PP16 | D7: 13
A8: - Dekstop | B8: 11 | C8: No Lisensi | D8: 5
A9: 2. Laptop | B9: 53 | C9: Total | D9: =SUM(D4:D8) -> 229
A10: Total | B10: =SUM(B4:B9) -> 229

Sheet PC  (detail)
E1: CLIENT PC ASSET LIST | AM1: INFORMASI PEMBELIAN
B2: UPDATE | E2: : FEB 2026
I3: Tahun | K3: Status | L3: KLASIFIKASI | Y3: LISENSI | AG3: IP ADDRESS MAIN | AH3: IP ADDRESS BACKUP | AI3: LISENSI MS OFFICE | AJ3: Windows | AK3: Trend Micro (Max PC & Svr 265) | AL3: Cybereason (Max PC & Svr 245)
B4: NO | C4: NO.ASSET | D4: TYPE | E4: DIVISI | F4: DEPT | G4: NAMA | H4: NIK | I4: Pembelian | J4: Depresiasi (5+1 Tahun) | M4: Managerial | N4: Meeting | O4: Aktivitas Khusus | P4: Officer Admin | Q4: Teknikal | R4: Operator | S4: Aplikasi WMS | T4: VMS | U4: CCTV View | V4: Station Delivery | W4: Aplikasi Gathering | X4: OQC | Y4: E3 | Z4: BB | AA4: OHB | AB4: INTUNE | AC4: AFB | AD4: EMAIL | AE4: SMX | AF4: HOSTNAME | AM4: SUPPLIER | AN4: NO PO | AO4: TAHUN BELI | AP4: BULAN DEPRESIASI | AQ4: PIC SUPPLIER | AR4: KONTAK SUPPLIER | AS4: REMARKS | AV4: SCHEDULE DISPOSE 2026
B5: 1 | C5: FI-00936 | D5: LAPTOP | E5: EXECUTIVE BOARD | F5: - | G5: KANTO SHIBATANI (X1 Carbon) | H5: 110501 | I5: 2024 | J5: =I5+6 -> 2030 | K5: ACTIVE | L5: LAPTOP MANAGERIAL | M5: ✓ | Y5: YA | AB5: YA | AC5: TIDAK | AD5: k-shibatani@ikoito.co.id | AE5: YA | AF5: PIK1COM049 | AG5: 172.17.12.19 | AH5: DHCP | AI5: E3 | AJ5: Windows 11 | AK5: 1 | AL5: 1 | AM5: CLARUS | AN5: 019/PO/HR&GA/GA/XII/2023 | AO5: 45261 | AP5: 47453 | AQ5: LUSY | AR5: 0811-1067-925 | AS5: LAPTOP ADD DES 2023
B6: 2 | C6: FI-00639 | D6: LAPTOP | E6: EXECUTIVE BOARD | F6: - | G6: MUTSUHIKO UCHIYAMA | H6: 1007001 | I6: 2021 | J6: =I6+6 -> 2027 | K6: ACTIVE | L6: LAPTOP MANAGERIAL | M6: ✓ | Y6: YA | AB6: YA | AC6: TIDAK | AD6: mu-uchiyama@ikoito.co.id | AE6: YA | AF6: PIKPC116 | AG6: 172.17.12.16 | AH6: DHCP | AI6: E3 | AJ6: Windows 11 | AK6: 1 | AL6: 1 | AM6: SBTELECOM | AN6: 023/PO/HR&GA/GA/ VI/2021 | AO6: 44348 | AP6: 46539 | AQ6: ASTRI | AR6: 0811-1067-925 | AS6: UPGRADE LAP MNGR JUNI 2021 (20 UNIT)
B7: 3 | C7: FI-00640 | D7: LAPTOP | E7: EXECUTIVE BOARD | F7: - | G7: SHIBATANI KANTO | H7: 110501 | I7: 2021 | J7: =I7+6 -> 2027 | K7: ACTIVE | L7: LAPTOP MANAGERIAL | M7: ✓ | Y7: YA | AB7: YA | AC7: TIDAK | AD7: k-shibatani@ikoito.co.id | AE7: YA | AF7: PIKPC106 | AG7: 172.17.12.18 | AH7: DHCP | AI7: E3 | AJ7: Windows 11 | AK7: 1 | AL7: 1 | AM7: SBTELECOM | AN7: 023/PO/HR&GA/GA/ VI/2021 | AO7: 44348 | AP7: 46539 | AQ7: ASTRI | AR7: 0811-1067-925 | AS7: UPGRADE LAP MNGR JUNI 2021 (20 UNIT)
B8: 4 | C8: FI-00641 | D8: LAPTOP | E8: EXECUTIVE BOARD | F8: - | G8: ERMA PURNAMA WIDA PANE | H8: 1008001 | I8: 2021 | J8: =I8+6 -> 2027 | K8: ACTIVE | L8: LAPTOP MANAGERIAL | M8: ✓ | Y8: YA | AB8: YA | AC8: TIDAK | AD8: erma@ikoito.co.id | AE8: YA | AF8: PIKPC107 | AG8: 172.17.12.31 | AH8: DHCP | AI8: E3 | AJ8: Windows 11 | AK8: 1 | AL8: 1 | AM8: SBTELECOM | AN8: 023/PO/HR&GA/GA/ VI/2021 | AO8: 44348 | AP8: 46539 | AQ8: ASTRI | AR8: 0811-1067-925 | AS8: UPGRADE LAP MNGR JUNI 2021 (20 UNIT)
B9: 5 | C9: FI-01114 | D9: ALL IN ONE | E9: FINANCE DIV | F9: FA | G9: MAUDICA FAMELA AGISTY PUTERI | H9: 2508023 | I9: 2025 | J9: =I9+6 -> 2031 | K9: ACTIVE | L9: OFFICER ADMIN | P9: ✓ | Z9: YA | AA9: YA | AC9: TIDAK | AD9: =VLOOKUP(C9,'[39]LAMPIRAN STANDAR'!$E$81:F$216,2,0) -> maudica.f@ikoito.co.id | AE9: YA | AF9: PIK1COM160 | AG9: 172.17.12.192 | AH9: 172.17.128.8 | AI9: OHB | AJ9: Windows 11 | AK9: 1 | AL9: 1 | AM9: SBTELECOM | AN9: 023/PO/HR&GA/GA/VII/2025 | AO9: 45839 | AP9: 48030 | AQ9: ASTRI | AR9: 0811-1067-925 | AS9: DEPRE JUL 2025
B10: 6 | C10: FI-01115 | D10: ALL IN ONE | E10: FINANCE DIV | F10: FA | G10: DIKA PRATAMA PUTRA | H10: 2601016 | I10: 2025 | J10: =I10+6 -> 2031 | K10: ACTIVE | L10: OFFICER ADMIN | P10: ✓ | Z10: YA | AA10: YA | AC10: TIDAK | AD10: =VLOOKUP(C10,'[39]LAMPIRAN STANDAR'!$E$81:F$216,2,0) -> accounting@ikoito.co.id | AE10: YA | AF10: PIK1COM161 | AG10: 172.17.12.197 | AH10: 172.17.128.7 | AI10: OHB | AJ10: Windows 11 | AK10: 1 | AL10: 1 | AM10: SBTELECOM | AN10: 023/PO/HR&GA/GA/VII/2025 | AO10: 45839 | AP10: 48030 | AQ10: ASTRI | AR10: 0811-1067-925 | AS10: DEPRE JUL 2025
B11: 7 | C11: FI-01026 | D11: ALL IN ONE | E11: FINANCE DIV | F11: FA | G11: ASTIANI PEBRIANA | H11: 2203040 | I11: 2024 | J11: =I11+6 -> 2030 | K11: ACTIVE | L11: OFFICER ADMIN | P11: ✓ | Z11: YA | AA11: YA | AC11: TIDAK | AD11: =VLOOKUP(C11,'[39]LAMPIRAN STANDAR'!$E$81:F$216,2,0) -> astiani.p@ikoito.co.id | AE11: YA | AF11: PIK1COM120 | AG11: 172.17.12.199 | AH11: 172.17.128.6 | AI11: OHB | AJ11: Windows 11 | AK11: 1 | AL11: 1 | AM11: TETRANET | AN11: 039/PO/HR&GA/GA/X/2024 | AO11: 45597 | AP11: 47788 | AQ11: AFDAL | AR11: 0831-8760-3905 | AS11: DEPRE NOV 2024
B12: 8 | C12: FI-00767 | D12: LAPTOP | E12: FINANCE DIV | F12: FA | G12: YAYAH ROHIYAH | H12: 1307002 | I12: 2023 | J12: =I12+6 -> 2029 | K12: ACTIVE | L12: LAPTOP MANAGERIAL | M12: ✓ | Y12: YA | Z12: TIDAK | AC12: TIDAK | AD12: yayah.r@ikoito.co.id | AE12: YA | AF12: PIK1COM023 | AG12: 172.17.12.189 | AH12: DHCP | AI12: E3 | AJ12: Windows 11 | AK12: 1 | AL12: 1 | AM12: CLARUS | AN12: 058/PO/HR&GA/GA/VI/2023 | AO12: 45108 | AP12: 47300 | AQ12: LUSY | AR12: 0856-9576-1612 | AS12: LAPTOP ADD JULI 2023 (5 UNIT)
B13: 9 | C13: FI-00775 | D13: ALL IN ONE | E13: FINANCE DIV | F13: FA | G13: FANI YULIANI | H13: 1505006 | I13: 2023 | J13: =I13+6 -> 2029 | K13: ACTIVE | L13: OFFICER ADMIN | P13: ✓ | Z13: YA | AA13: YA | AC13: TIDAK | AD13: =VLOOKUP(C13,'[39]LAMPIRAN STANDAR'!$E$81:F$216,2,0) -> fani.y@ikoito.co.id | AE13: YA | AF13: PIK1COM016 | AG13: 172.17.12.191 | AH13: 172.17.128.5 | AI13: OHB | AJ13: Windows 11 | AK13: 1 | AL13: 1 | AM13: DARUMA | AN13: 049/PO/HR&GA/GA/V/2023 | AO13: 45047 | AP13: 47239 | AQ13: RINDU | AR13: - | AS13: PC DEPRE MEI 2023
B14: 10 | C14: FI-00927 | D14: ALL IN ONE | E14: FINANCE DIV | F14: FA | G14: FERA PEBRIANA | H14: 1403005 | I14: 2023 | J14: =I14+6 -> 2029 | K14: ACTIVE | L14: OFFICER ADMIN | P14: ✓ | Z14: YA | AA14: YA | AC14: TIDAK | AD14: =VLOOKUP(C14,'[39]LAMPIRAN STANDAR'!$E$81:F$216,2,0) -> fera.p@ikoito.co.id | AE14: YA | AF14: PIK1COM044 | AG14: 172.17.12.190 | AH14: 172.17.128.4 | AI14: OHB | AJ14: Windows 11 | AK14: 1 | AL14: 1 | AM14: DARUMA | AN14: 023/PO/HR&GA/GA/XI/2023 | AO14: 45231 | AP14: 47423 | AQ14: RINDU | AR14: - | AS14: PC DEPRE NOV 2023
B15: 11 | C15: FI-00670 | D15: ALL IN ONE | E15: FINANCE DIV | F15: FA | G15: STEVE FANNIE | H15: 1011032 | I15: 2022 | J15: =I15+6 -> 2028 | K15: ACTIVE | L15: AKTIVITAS KHUSUS | O15: ✓ | Z15: YA | AC15: YA | AD15: fannie@ikoito.co.id | AE15: YA | AF15: PIKPC132 | AG15: 172.17.12.188 | AH15: 172.17.128.3 | AI15: AFB | AJ15: Windows 11 | AK15: 1 | AL15: 1 | AM15: SBTELECOM | AN15: 024/PO/HR&GA/GA/VI/2021 | AO15: 44348 | AP15: 46539 | AQ15: ASTRI | AR15: 0811-1067-925 | AS15: UPGRADE AIO JUNI 2021 (18 UNIT)
B16: 12 | C16: FI-00607 | D16: LAPTOP | E16: FINANCE DIV | F16: FA | G16: IMAN KOESTIAMAN | H16: 1112021 | I16: 2021 | J16: =I16+6 -> 2027 | K16: ACTIVE | L16: LAPTOP MANAGERIAL | M16: ✓ | Y16: YA | Z16: TIDAK | AC16: TIDAK | AD16: iman.k@ikoito.co.id | AE16: YA | AF16: PIKLT004 | AG16: 172.17.12.186 | AH16: DHCP | AI16: E3 | AJ16: Windows 11 | AK16: 1 | AL16: 1 | AM16: CLARUS | AN16: 028/PO/HR&GA/GA/ I/2021 | AO16: 44348 | AP16: 46388 | AQ16: LUSY | AR16: 0856-9576-1612 | AS16: PC DEPRE JAN 2021
B17: 13 | C17: FI-01104 | D17: ALL IN ONE | E17: GENERAL AFFAIR DIV | F17: HRGA | G17: GA (NURUSSYIFA MAULIDA) | H17: 1510015 | I17: 2025 | J17: =I17+6 -> 2031 | K17: ACTIVE | L17: OPERATOR | R17: ✓ | Z17: TIDAK | AA17: YA | AC17: TIDAK | AD17: - | AE17: TIDAK | AF17: PIK1COM149 | AG17: 172.17.12.76 | AH17: 172.17.128.27 | AI17: OHB | AJ17: Windows 11 | AK17: 1 | AL17: 1 | AM17: SBTELECOM | AN17: 032/PO/HR&GA/GA/VI/2025 | AO17: 45778 | AP17: 47969 | AQ17: ASTRI | AR17: 0811-1067-925 | AS17: DEPRE MEI 2025
B18: 14 | C18: FI-01094 | D18: LAPTOP | E18: GENERAL AFFAIR DIV | F18: HR GA | G18: PAYROLL (ERNA) | H18: 1208059 | I18: 2025 | J18: =I18+6 -> 2031 | K18: ACTIVE | L18: LAPTOP MANAGERIAL | M18: ✓ | Y18: YA | Z18: TIDAK | AA18: TIDAK | AC18: TIDAK | AD18: payroll@ikoito.co.id | AE18: YA | AF18: PIK1COM152 | AG18: 172.17.12.37 | AH18: DHCP | AI18: E3 | AJ18: Windows 11 | AK18: 1 | AL18: 1 | AM18: SBTELECOM | AN18: 034/PO/HR&GA/GA/VI/2025 | AO18: 45748 | AP18: 47939 | AQ18: ASTRI | AR18: 0811-1067-925 | AS18: DEPRE APR 2025
B19: 15 | C19: FI-01019 | D19: ALL IN ONE | E19: GENERAL AFFAIR DIV | F19: HR GA | G19: DHIGTA OKTORIA | H19: 2508022 | I19: 2024 | J19: =I19+6 -> 2030 | K19: ACTIVE | L19: OFFICER ADMIN | P19: ✓ | Y19: TIDAK | Z19: YA | AA19: YA | AC19: TIDAK | AD19: =VLOOKUP(C19,'[39]LAMPIRAN STANDAR'!$E$81:F$216,2,0) -> ga@ikoito.co.id | AE19: YA | AF19: PIK1COM109 | AG19: 172.17.12.75 | AH19: 172.17.128.14 | AI19: OHB | AJ19: Windows 11 | AK19: 1 | AL19: 1 | AM19: TETRANET | AN19: 009/PO/HR&GA/GA/X/2024 | AO19: 45566 | AP19: 47757 | AQ19: AFDAL | AR19: 0831-8760-3905 | AS19: DEPRE OKT 2024
B20: 16 | C20: FI-01004 | D20: ALL IN ONE | E20: GENERAL AFFAIR DIV | F20: HR GA | G20: ANDRI FAISAL | H20: 1411001 | I20: 2024 | J20: =I20+6 -> 2030 | K20: ACTIVE | L20: OFFICER ADMIN | P20: ✓ | Y20: TIDAK | Z20: YA | AA20: YA | AB20: TIDAK | AC20: TIDAK | AD20: =VLOOKUP(C20,'[39]LAMPIRAN STANDAR'!$E$81:F$216,2,0) -> andri.f@ikoito.co.id | AE20: YA | AF20: PIK1COM102 | AG20: 172.17.12.45 | AH20: 172.17.128.12 | AI20: OHB | AJ20: Windows 11 | AK20: 1 | AL20: 1 | AM20: RBS | AN20: 041/PO/HR&GA/GA/VIII/2024 | AO20: 45505 | AP20: 47696 | AQ20: SANJAYA | AR20: 0858-8878-8800 | AS20: DEPRE AGUST 2024
B21: 17 | C21: FI-01003 | D21: ALL IN ONE | E21: GENERAL AFFAIR DIV | F21: HR GA | G21: HR RECRUITMENT (KAMILAH) | H21: 1109018 | I21: 2024 | J21: =I21+6 -> 2030 | K21: ACTIVE | L21: OFFICER ADMIN | P21: ✓ | Y21: TIDAK | Z21: YA | AA21: YA | AB21: TIDAK | AC21: TIDAK | AD21: =VLOOKUP(C21,'[39]LAMPIRAN STANDAR'!$E$81:F$216,2,0) -> recruitment@ikoito.co.id | AE21: YA | AF21: PIK1COM100 | AG21: 172.17.12.54 | AH21: 172.17.128.13 | AI21: OHB | AJ21: Windows 11 | AK21: 1 | AL21: 1 | AM21: RBS | AN21: 041/PO/HR&GA/GA/VIII/2024 | AO21: 45505 | AP21: 47696 | AQ21: SANJAYA | AR21: 0858-8878-8800 | AS21: DEPRE AGUST 2024
B22: 18 | C22: FI-00981 | D22: ALL IN ONE | E22: GENERAL AFFAIR DIV | F22: HR GA | G22: ERNA YULIAWATI | H22: 1208059 | I22: 2024 | J22: =I22+6 -> 2030 | K22: ACTIVE | L22: OFFICER ADMIN | P22: ✓ | Y22: TIDAK | Z22: YA | AA22: YA | AB22: TIDAK | AC22: TIDAK | AD22: =VLOOKUP(C22,'[39]LAMPIRAN STANDAR'!$E$81:F$216,2,0) -> erna@ikoito.co.id | AE22: YA | AF22: PIK1COM084 | AG22: 172.17.12.43 | AH22: 172.17.128.11 | AI22: OHB | AJ22: Windows 11 | AK22: 1 | AL22: 1 | AM22: SBTELECOM | AN22: 007/PO/HR&GA/GA/V/2024 | AO22: 45413 | AP22: 47604 | AQ22: ASTRI | AR22: 0811-1067-925 | AS22: PERCEPATAN MEI 2024
B23: 19 | C23: FI-00960 | D23: ALL IN ONE | E23: GENERAL AFFAIR DIV | F23: HR GA | G23: SUSINTAWATI (TC) | H23: 1208058 | I23: 2024 | J23: =I23+6 -> 2030 | K23: ACTIVE | L23: OFFICER ADMIN | P23: ✓ | Y23: TIDAK | Z23: YA | AA23: YA | AB23: TIDAK | AC23: TIDAK | AD23: =VLOOKUP(C23,'[39]LAMPIRAN STANDAR'!$E$81:F$216,2,0) -> hr-training@ikoito.co.id | AE23: YA | AF23: PIK1COM056 | AG23: 172.17.12.47 | AH23: 172.17.128.15 | AI23: OHB | AJ23: Windows 11 | AK23: 1 | AL23: 1 | AM23: SBTELECOM | AN23: 063/PO/HR&GA/GA/I/2024 | AO23: 45292 | AP23: 47484 | AQ23: ASTRI | AR23: 0811-1067-925 | AS23: PC DEPRE JAN 2024
B24: 20 | C24: FI-00787 | D24: LAPTOP | E24: GENERAL AFFAIR DIV | F24: HR GA | G24: TC (AYUNG) | H24: 1205001 | I24: 2023 | J24: =I24+6 -> 2029 | K24: ACTIVE | L24: LAPTOP MANAGERIAL | M24: ✓ | Y24: TIDAK | Z24: TIDAK | AA24: TIDAK | AB24: TIDAK | AC24: TIDAK | AD24: - | AE24: TIDAK | AF24: PIK1COM035 | AG24: 172.17.12.48 | AH24: DHCP | AI24: E3 | AJ24: Windows 11 | AK24: 1 | AL24: 1 | AM24: DARUMA | AN24: 043/PO/HR&GA/GA/VIII/2023 | AO24: 45139 | AP24: 47331 | AQ24: RINDU | AR24: - | AS24: LAPTOP DEPRE AGUST 2023
B25: 21 | C25: FI-00660 | D25: ALL IN ONE | E25: GENERAL AFFAIR DIV | F25: HR GA | G25: HR PAYROLL (RINDY) | H25: 2602032 | I25: 2022 | J25: =I25+6 -> 2028 | K25: ACTIVE | L25: OFFICER ADMIN | P25: ✓ | Y25: TIDAK | Z25: YA | AA25: YA | AB25: TIDAK | AC25: TIDAK | AD25: =VLOOKUP(C25,'[39]LAMPIRAN STANDAR'!$E$81:F$216,2,0) -> hr1@ikoito.co.id | AE25: YA | AF25: PIKPC122 | AG25: 172.17.12.222 | AH25: 172.17.128.16 | AI25: OHB | AJ25: Windows 11 | AK25: 1 | AL25: 1 | AM25: SBTELECOM | AN25: 024/PO/HR&GA/GA/VI/2021 | AO25: 44348 | AP25: 46539 | AQ25: ASTRI | AR25: 0811-1067-925 | AS25: UPGRADE AIO JUNI 2021 (18 UNIT)
B26: 22 | C26: FI-00762 | D26: LAPTOP | E26: GENERAL AFFAIR DIV | F26: HRGA | G26: DEPARTEMEN HEAD HR&GA (HAFIDZ) | H26: 1101138 | I26: 2023 | J26: =I26+6 -> 2029 | K26: ACTIVE | L26: LAPTOP MANAGERIAL | M26: ✓ | Y26: YA | Z26: TIDAK | AA26: TIDAK | AB26: TIDAK | AC26: TIDAK | AD26: hafidz.ardiansyah@ikoito.co.id | AE26: YA | AF26: PIK1COM022 | AG26: 172.17.12.71 | AH26: DHCP | AI26: E3 | AJ26: Windows 11 | AK26: 1 | AL26: 1 | AM26: CLARUS | AN26: 059/PO/HR&GA/GA/VI/2023 | AO26: 45078 | AP26: 47270 | AQ26: LUSY | AR26: 0856-9576-1612 | AS26: PC DEPRE JUNI 2023
B27: 23 | C27: FI-00654 | D27: LAPTOP | E27: GENERAL AFFAIR DIV | F27: HRGA | G27: KOITO M-14 (ERNA) | H27: 1205001 | I27: 2021 | J27: =I27+6 -> 2027 | K27: ACTIVE | L27: LAPTOP MEETING | N27: ✓ | Y27: TIDAK | Z27: TIDAK | AA27: TIDAK | AB27: TIDAK | AC27: TIDAK | AD27: - | AE27: TIDAK | AF27: PIKPC115 | AG27: 172.17.12.214 | AH27: DHCP | AI27: E3 | AJ27: Windows 11 | AK27: 1 | AL27: 1 | AM27: SBTELECOM | AN27: 023/PO/HR&GA/GA/ VI/2021 | AO27: 44348 | AP27: 46539 | AQ27: ASTRI | AR27: 0811-1067-925 | AS27: UPGRADE LAP MNGR JUNI 2021 (20 UNIT)
B28: 24 | C28: FI-00537 | D28: MINI PC | E28: GENERAL AFFAIR DIV | F28: HR GA | G28: HR SH | I28: 43826 | J28: =EDATE(I28,72) -> 46018 | K28: ACTIVE | L28: OFFICER ADMIN | P28: ✓ | Y28: TIDAK | Z28: YA | AA28: YA | AB28: TIDAK | AC28: TIDAK | AD28: =VLOOKUP(C28,'[39]LAMPIRAN STANDAR'!$E$81:F$216,2,0) -> hr-sh@ikoito.co.id | AE28: YA | AF28: PIKPC034 | AG28: 172.17.12.49 | AH28: 172.17.128.26 | AI28: PP16 | AJ28: Windows 11 | AK28: 1 | AL28: 1 | AM28: CLARUS | AN28: 011/PO/HR&GA/GA/VIII/2019 | AO28: 43678 | AP28: 45870 | AQ28: LUSY | AR28: 0856-9576-1612 | AS28: PC DEPRE AGUST 2019
B29: 25 | C29: FI-00532 | D29: LAPTOP | E29: GENERAL AFFAIR DIV | F29: HR GA | G29: KOITO M-07 EX:ARDI/CAHYO) | H29: 1208059 | I29: 43826 | J29: =EDATE(I29,72) -> 46018 | K29: ACTIVE | L29: LAPTOP MEETING | N29: ✓ | Y29: TIDAK | Z29: TIDAK | AA29: TIDAK | AB29: TIDAK | AC29: TIDAK | AD29: - | AE29: TIDAK | AF29: PIK1COM072 | AG29: - | AH29: DHCP | AI29: E3 | AJ29: Windows 11 | AK29: 1 | AL29: 1 | AM29: CLARUS | AN29: 009/PO/HR&GA/GA/VIII/2019 | AO29: 43678 | AP29: 45870 | AQ29: LUSY | AR29: 0856-9576-1612 | AS29: PC DEPRE AGUST 2019
B30: 26 | C30: FI-00413 | D30: LAPTOP | E30: GENERAL AFFAIR DIV | F30: HRGA | G30: KOITO M-13 (ERNA) | H30: 1208059 | I30: 43455 | J30: =EDATE(I30,72) -> 45647 | K30: ACTIVE | L30: LAPTOP MEETING | N30: ✓ | Y30: TIDAK | Z30: TIDAK | AA30: TIDAK | AB30: TIDAK | AC30: TIDAK | AD30: - | AE30: TIDAK | AF30: ENGMGRLT001 | AG30: - | AH30: DHCP | AI30: E3 | AJ30: Windows 11 | AK30: 1 | AL30: 1 | AM30: CSI | AN30: 011/PO/HR&GA/GA/X/2018 | AO30: 43374 | AP30: 45566 | AQ30: IBRAIM | AR30: 0812-8097-4409 | AS30: PC ADD OKT 2018
B31: 27 | C31: FI-00412 | D31: LAPTOP | E31: GENERAL AFFAIR DIV | F31: HR GA | G31: KOITO M-19 (ERNA) | H31: 1208059 | I31: 43455 | J31: =EDATE(I31,72) -> 45647 | K31: ACTIVE | L31: LAPTOP MEETING | N31: ✓ | Y31: TIDAK | Z31: TIDAK | AA31: TIDAK | AB31: TIDAK | AC31: TIDAK | AD31: - | AE31: TIDAK | AF31: PIK1COM002 | AG31: - | AH31: DHCP | AI31: E3 | AJ31: Windows 11 | AK31: 1 | AL31: 1 | AM31: CSI | AN31: 011/PO/HR&GA/GA/X/2018 | AO31: 43374 | AP31: 45566 | AQ31: IBRAIM | AR31: 0812-8097-4409 | AS31: PC ADD OKT 2018
B32: 28 | C32: BELUM AKUISISI | D32: WORKSTATION | E32: GENERAL AFFAIR DIV | F32: IT LEGAL | G32: DARYANA | H32: 1801046 | I32: 2026 | J32: =I32+6 -> 2032 | K32: ACTIVE | L32: TEKNIKAL | Q32: ✓ | Y32: TIDAK | Z32: YA | AA32: YA | AB32: TIDAK | AC32: TIDAK | AD32: it.dx@ikoito.co.id | AE32: YA | AF32: PIK1COM191 | AG32: 172.17.12.66 | AH32: 172.17.128.41 | AI32: OHB | AJ32: Windows 11 | AK32: 1 | AL32: 1 | AM32: SBTELECOM | AN32: 021/PO/HR&GA/GA/XI/2026 | AO32: 46023 | AP32: 48214 | AQ32: ASTRI | AR32: 0811-1067-925 | AS32: ADD JAN 2026
B33: 29 | C33: FI-01100 | D33: ALL IN ONE | E33: GENERAL AFFAIR DIV | F33: IT LEGAL | G33: TRANSFER DATA LOG IT (AYUNG) | H33: 1701036 | I33: 2025 | J33: =I33+6 -> 2031 | K33: ACTIVE | L33: OPERATOR | R33: ✓ | Y33: TIDAK | Z33: TIDAK | AA33: YA | AB33: TIDAK | AC33: TIDAK | AD33: - | AE33: TIDAK | AF33: PIK1COM156 | AG33: 172.17.12.57 | AH33: 172.17.128.38 | AI33: OHB | AJ33: Windows 11 | AK33: 1 | AL33: 1 | AM33: SBTELECOM | AN33: 045/PO/HR&GA/GA/VI/2025 | AO33: 45778 | AP33: 47969 | AQ33: ASTRI | AR33: 0811-1067-925 | AS33: DEPRE MEI 2025
B34: 30 | C34: FI-01071 | D34: ALL IN ONE | E34: GENERAL AFFAIR DIV | F34: IT LEGAL | G34: SARI REZEKI | H34: 1402011 | I34: 2025 | J34: 2030 | K34: ACTIVE | L34: OFFICER ADMIN | P34: ✓ | Y34: TIDAK | Z34: YA | AA34: YA | AB34: TIDAK | AC34: TIDAK | AD34: =VLOOKUP(C34,'[39]LAMPIRAN STANDAR'!$E$81:F$216,2,0) -> legal-control@ikoito.co.id | AE34: YA | AF34: PIK1COM140 | AG34: 172.17.12.53 | AH34: 172.17.128.39 | AI34: OHB | AJ34: Windows 11 | AK34: 1 | AL34: 1 | AM34: XDC | AN34: 011/PO/HR&GA/GA/III/2025 | AO34: 45717 | AP34: 47908 | AQ34: WIDI | AR34: 0821-2106-7715 | AS34: PERCEPATAN MAR 2025 (14 UNIT)
AD35: gratifikasi@ikoito.co.id
B36: 31 | C36: FI-01062 | D36: ALL IN ONE | E36: GENERAL AFFAIR DIV | F36: IT LEGAL | G36: ADNI AGESTIAN VIRZY | H36: 1605033 | I36: 2025 | J36: =I36+6 -> 2031 | K36: ACTIVE | L36: OFFICER ADMIN | P36: ✓ | Y36: TIDAK | Z36: YA | AA36: YA | AB36: TIDAK | AC36: TIDAK | AD36: =VLOOKUP(C36,'[39]LAMPIRAN STANDAR'!$E$81:F$216,2,0) -> ir@ikoito.co.id | AE36: YA | AF36: PIK1COM136 | AG36: 172.17.12.65 | AH36: 172.17.128.40 | AI36: OHB | AJ36: Windows 11 | AK36: 1 | AL36: 1 | AM36: XDC | AN36: 012/PO/HR&GA/GA//III/2025 | AO36: 45689 | AP36: 47880 | AQ36: WIDI | AR36: 0821-2106-7715 | AS36: PERCEPATAN FEB 2025 (14 UNIT)
B37: 32 | C37: FI-01025 | D37: ALL IN ONE | E37: GENERAL AFFAIR DIV | F37: IT LEGAL | G37: YULYAYU KURNIAWATI | H37: 1210042 | I37: 2024 | J37: =I37+6 -> 2030 | K37: ACTIVE | L37: OFFICER ADMIN | P37: ✓ | Y37: TIDAK | Z37: YA | AA37: YA | AB37: TIDAK | AC37: TIDAK | AD37: =VLOOKUP(C37,'[39]LAMPIRAN STANDAR'!$E$81:F$216,2,0) -> compliance@ikoito.co.id | AE37: YA | AF37: PIK1COM119 | AG37: 172.17.12.41 | AH37: 172.17.128.45 | AI37: OHB | AJ37: Windows 11 | AK37: 1 | AL37: 1 | AM37: TETRANET | AN37: 039/PO/HR&GA/GA/X/2024 | AO37: 45597 | AP37: 47788 | AQ37: AFDAL | AR37: 0831-8760-3905 | AS37: DEPRE NOV 2024
B38: 33 | C38: FI-00987 | D38: ALL IN ONE | E38: GENERAL AFFAIR DIV | F38: IT LEGAL | G38: DEVITA DWI ANGGRAENI | H38: 2403012 | I38: 2024 | J38: =I38+6 -> 2030 | K38: ACTIVE | L38: OFFICER ADMIN | P38: ✓ | Y38: TIDAK | Z38: YA | AA38: YA | AB38: TIDAK | AC38: TIDAK | AD38: =VLOOKUP(C38,'[39]LAMPIRAN STANDAR'!$E$81:F$216,2,0) -> it.admin@ikoito.co.id | AE38: YA | AF38: PIK1COM098 | AG38: 172.17.12.59 | AH38: 172.17.128.35 | AI38: OHB | AJ38: Windows 11 | AK38: 1 | AL38: 1 | AM38: TETRANET | AN38: 034/PO/HR&GA/GA/VI/2024 | AO38: 45444 | AP38: 47635 | AQ38: AFDAL | AR38: 0831-8760-3905 | AS38: DEPRE JUNI 2024
B39: 34 | C39: FI-00969 | D39: WORKSTATION | E39: GENERAL AFFAIR DIV | F39: ITLEGAL | G39: MOHAMAD FAHMY IQBAL | H39: 1803070 | I39: 2024 | J39: =I39+6 -> 2030 | K39: ACTIVE | L39: TEKNIKAL | Q39: ✓ | Y39: TIDAK | Z39: YA | AA39: YA | AB39: TIDAK | AC39: TIDAK | AD39: fahmy.i@ikoito.co.id | AE39: YA | AF39: PIK1COM074 | AG39: 172.17.12.63 | AH39: 172.17.128.34 | AI39: OHB | AJ39: Windows 11 | AK39: 1 | AL39: 1 | AM39: SBTELECOM | AN39: 028/PO/HR/GA/GA/V/2024 | AO39: 45413 | AP39: 47604 | AQ39: ASTRI | AR39: 0811-1067-925 | AS39: DEPRE MEI 2024
B40: 35 | C40: FI-00783 | D40: ALL IN ONE | E40: GENERAL AFFAIR DIV | F40: IT LEGAL | G40: FADHI WINIATAMA | H40: 1309033 | I40: 2023 | J40: =I40+6 -> 2029 | K40: ACTIVE | L40: OFFICER ADMIN | P40: ✓ | Y40: TIDAK | Z40: YA | AA40: YA | AB40: TIDAK | AC40: TIDAK | AD40: =VLOOKUP(C40,'[39]LAMPIRAN STANDAR'!$E$81:F$216,2,0) -> fadhi.w@ikoito.co.id | AE40: YA | AF40: PIK1COM036 | AG40: 172.17.12.61 | AH40: 172.17.128.33 | AI40: OHB | AJ40: Windows 11 | AK40: 1 | AL40: 1 | AM40: DARUMA | AN40: 019/PO/HR&GA/GA/VIII/2023 | AO40: 45139 | AP40: 47331 | AQ40: RINDU | AR40: - | AS40: PC DEPRE AGUST 2023
...

Sheet PC NG
C1: CLIENT PC ASSET LIST | Z1: INFORMASI PEMBELIAN
A2: UPDATE | D2: : FEB 2026
D3: USER | M3: Klasifikasi User | Z3: SUPPLIER | AA3: NO PO | AB3: PIC SUPPLIER | AC3: KONTAK SUPPLIER | AD3: REMARKS
A4: NO | B4: NO.ASSET | C4: TYPE | D4: DIVISI | E4: DEPT | F4: NAMA | G4: NIK | H4: Pembelian | I4: Depresiasi (5+1 Tahun) | J4: HOSTNAME | K4: IP ADDRESS MAIN | L4: IP ADDRESS BACKUP | M4: Managerial | N4: Meeting | O4: Aktivitas Khusus | P4: Officer Admin | Q4: Teknikal | R4: Operator | S4: Aplikasi WMS | T4: VMS | U4: CCTV View | V4: Station Delivery | W4: Aplikasi Gathering | X4: OQC | Y4: Status
A5: 1 | B5: FI-00412 | C5: LAPTOP | D5: GENERAL AFFAIR DIV | E5: HR GA | F5: KOITO M-19 (ERNA) | G5: 1208059 | H5: 43455 | I5: 45647 | J5: PIK1COM002 | K5: - | L5: DHCP | N5: ✓ | Y5: ACTIVE | Z5: CSI | AA5: 011/PO/HR&GA/GA/X/2018 | AB5: IBRAIM | AC5: 0812-8097-4409 | AD5: PC ADD OKT 2018
A6: 2 | B6: FI-00413 | C6: LAPTOP | D6: GENERAL AFFAIR DIV | E6: HR GA | F6: KOITO M-13 (ERNA) | G6: 1208059 | H6: 43455 | I6: 45647 | J6: ENGMGRLT001 | K6: - | L6: DHCP | N6: ✓ | Y6: ACTIVE | Z6: CSI | AA6: 011/PO/HR&GA/GA/X/2018 | AB6: IBRAIM | AC6: 0812-8097-4409 | AD6: PC ADD OKT 2018
A7: 3 | B7: FI-00507 | C7: ALL IN ONE | D7: INJECTION MOLD DIV | E7: MOLD MAKING | F7: ANDINI SEPTOWATI | G7: 1506019 | H7: 43732 | I7: 45924 | J7: MEPC010 | K7: 172.17.12.157 | L7: 172.17.128.57 | P7: ✓ | Y7: ACTIVE | Z7: SBTELECOM | AA7: - | AB7: ASTRI | AD7: PC DEPRE DES 2025
A8: 4 | B8: FI-00509 | C8: ALL IN ONE | D8: PART PROCESS DIV | E8: ASSEMBLING | F8: RENI MAROZA | G8: 1109101 | H8: 43732 | I8: 45924 | J8: ASSYPC022 | K8: 172.17.11.69 | L8: 172.17.118.31 | P8: ✓ | Y8: ACTIVE | Z8: SBTELECOM | AA8: - | AB8: ASTRI | AC8: 0856-9576-1612 | AD8: PC DEPRE DES 2025
A9: 5 | B9: FI-00526 | C9: ALL IN ONE | D9: KPS | E9: KPS | F9: EX: DENIS | G9: - | H9: 43796 | I9: 45988 | J9: KPSPC001 | K9: 172.17.11.53 | L9: 172.17.118.25 | R9: ✓ | Y9: ACTIVE | Z9: SBTELECOM | AA9: - | AB9: ASTRI | AD9: PC DEPRE DES 2025
A10: 6 | B10: FI-00527 | C10: ALL IN ONE | D10: PART PROCESS DIV | E10: ASSEMBLING | F10: RAMLAN HIKMAT | G10: 1108001 | H10: 43796 | I10: 45988 | J10: PIKPC003 | K10: 172.17.11.67 | L10: 172.17.118.27 | P10: ✓ | Y10: ACTIVE | Z10: SBTELECOM | AA10: - | AB10: ASTRI | AD10: PC DEPRE JAN 2026
A11: 7 | B11: FI-00532 | C11: LAPTOP | D11: GENERAL AFFAIR DIV | E11: HR GA | F11: KOITO M-07 EX:ARDI/CAHYO) | G11: 1208059 | H11: 43826 | I11: 46018 | J11: PIK1COM072 | K11: - | L11: DHCP | N11: ✓ | Y11: ACTIVE | Z11: CLARUS | AA11: 009/PO/HR&GA/GA/VIII/2019 | AB11: LUSY | AC11: 0856-9576-1612 | AD11: PC DEPRE AGUST 2019
A12: 8 | B12: FI-00533 | C12: MINI PC | D12: PART PROCESS DIV | E12: ST | F12: AMUD | G12: 1808002 | H12: 43826 | I12: 46018 | J12: SFTPC001 | K12: 172.17.11.49 | L12: 172.17.118.43 | P12: ✓ | Y12: ACTIVE | Z12: CLARUS | AA12: 054/PO/HR&GA/GA/VII/2019 | AB12: LUSY | AC12: 0856-9576-1612 | AD12: PC ADD JUL 2019
A13: 9 | B13: FI-00534 | C13: ALL IN ONE | D13: QE DIV | E13: PROD DEV | F13: PUJI EFENDI | G13: 1405012 | H13: 43826 | I13: 46018 | J13: PIK1COM092 | K13: 172.17.12.146 | L13: 172.17.128.134 | P13: ✓ | Y13: ACTIVE | Z13: SBTELECOM | AB13: ASTRI | AD13: PC DEPRE JAN 2026
A14: 10 | B14: FI-00535 | C14: ALL IN ONE | D14: PART PROCESS DIV | E14: ASSEMBLING | F14: ABU KHAMID | G14: 1302034 | H14: 43826 | I14: 46018 | J14: ASSYPC026 | K14: 172.17.11.101 | L14: 172.17.118.28 | P14: ✓ | Y14: ACTIVE | Z14: SBTELECOM | AA14: - | AB14: ASTRI | AD14: PC DEPRE JAN 2026
A15: 11 | B15: FI-00536 | C15: MINI PC | D15: KPS | E15: KPS | F15: SYAIFUL RAMADHAN | G15: 1302030 | H15: 43826 | I15: 46018 | J15: KPSPC002 | K15: 172.17.11.52 | L15: 172.17.118.23 | P15: ✓ | Y15: ACTIVE | Z15: CLARUS | AA15: 010/PO/HR&GA/GA/VIII/2019 | AB15: LUSY | AC15: 0856-9576-1612 | AD15: PC DEPRE AGUST 2019
A16: 12 | B16: FI-00537 | C16: MINI PC | D16: GENERAL AFFAIR DIV | E16: HR GA | F16: HR SH | H16: 43826 | I16: 46018 | J16: PIKPC034 | K16: 172.17.12.49 | L16: 172.17.128.26 | P16: ✓ | Y16: ACTIVE | Z16: CLARUS | AA16: 011/PO/HR&GA/GA/VIII/2019 | AB16: LUSY | AC16: 0856-9576-1612 | AD16: PC DEPRE AGUST 2019
A17: 13 | B17: FI-00538 | C17: MINI PC | D17: PART PROCESS DIV | E17: INJECTION | F17: INJ GROUP LEADER (ANDRIE SUHERMAN) | G17: 1011021 | H17: 43826 | I17: 46018 | J17: INJPC004 | K17: 172.17.11.42 | L17: 172.17.118.38 | P17: ✓ | Y17: ACTIVE | Z17: CLARUS | AA17: 011/PO/HR&GA/GA/VIII/2019 | AB17: LUSY | AC17: 0856-9576-1612 | AD17: PC DEPRE AGUST 2019
A18: 14 | B18: FI-00541 | C18: WORKSTATION | D18: INJECTION MOLD DIV | E18: MOLD MAKING | F18: MOLD DRAW PC (REZA ADITYA PERMADI) | G18: 2412013 | H18: 43826 | I18: 46018 | J18: MEDRAWPC001 | K18: 172.17.20.134 | L18: 172.17.218.8 | Q18: ✓ | Y18: Non Active | Z18: CSI | AA18: 012/PO/HR&GA/GA/IX/2019 | AB18: IBRAIM | AC18: 0812-8097-4409 | AD18: PC DEPRE SEP 2019
A19: 15 | B19: FI-00545 | C19: MINI PC | D19: QA DIV | E19: QT | F19: PANDU PRAMUDYA | G19: 1503046 | H19: 43861 | I19: 46053 | J19: QTPC001 | K19: 172.17.12.183 | L19: 172.17.128.118 | R19: ✓ | Y19: ACTIVE | Z19: CLARUS | AA19: 054/PO/HR&GA/GA/VII/2019 | AB19: LUSY | AC19: 0856-9576-1612 | AD19: PC ADD JUL 2019
A20: 16 | B20: FI-00547 | C20: MINI PC | D20: TECHNICAL DIV | E20: PROD ENG | F20: ARITONANG ARIA KUSUMA | G20: 1011015 | H20: 43861 | I20: 46053 | J20: ENGPC004 | K20: 172.17.11.78 | L20: 172.17.118.88 | P20: ✓ | Y20: ACTIVE | Z20: CLARUS | AA20: 012/PO/HR&GA/GA/VIII/2019 | AB20: LUSY | AC20: 0856-9576-1612 | AD20: PC DEPRE AGUST 2019
A21: 17 | B21: FI-00549 | C21: MINI PC | D21: PART PROCESS DIV | E21: ASSEMBLING | F21: ASSEMBLY GRUP LEADER (KUSNO) | G21: 1302038 | H21: 43861 | I21: 46053 | J21: PIKPC023 | K21: 172.17.11.100 | L21: 172.17.118.30 | P21: ✓ | Y21: Non Active | Z21: CLARUS | AA21: 011/PO/HR&GA/GA/VIII/2019 | AB21: LUSY | AC21: 0856-9576-1612 | AD21: PC DEPRE AGUST 2019
A22: 18 | B22: FI-00590 | C22: WORKSTATION | D22: INJECTION MOLD DIV | E22: MOLD ENG | F22: CAMTOOL CNC (ALKINDI) | G22: 1703001 | H22: 44227 | I22: 46418 | J22: MEDRAWPC002 | K22: 172.17.20.132 | L22: 172.17.218.4 | Q22: ✓ | Y22: ACTIVE | Z22: CLARUS | AA22: 025/PO/HR&GA/GA/X/2020 | AB22: LUSY | AC22: 0856-9576-1612 | AD22: PC DEPRE OKT 2020
A23: 19 | B23: FI-00591 | C23: WORKSTATION | D23: INJECTION MOLD DIV | E23: MOLD ENG | F23: MOLDFLOW (ISMAIL MARJUKI) | G23: 1801027 | H23: 44227 | I23: 46418 | J23: PIK1COM011 | K23: 172.17.12.163 | L23: 172.17.128.56 | Q23: ✓ | Y23: ACTIVE | Z23: CLARUS | AA23: 025/PO/HR&GA/GA/X/2020 | AB23: LUSY | AC23: 0856-9576-1612 | AD23: PC DEPRE OKT 2020
A24: 20 | B24: FI-00605 | C24: LAPTOP | D24: TECHNICAL DIV | E24: TECHNICAL DIV | F24: EDI KUSNADI | G24: 1011031 | H24: 44286 | I24: 46477 | J24: PIKLT003 | K24: 172.17.11.24 | L24: DHCP | M24: ✓ | Y24: ACTIVE | Z24: CLARUS | AA24: 028/PO/HR&GA/GA/ I/2021 | AB24: LUSY | AC24: 0856-9576-1612 | AD24: PC DEPRE JAN 2021
A25: 21 | B25: FI-00606 | C25: LAPTOP | D25: QA DIV | E25: QA DIV | F25: UJANG SOPANDI | G25: 1106001 | H25: 44286 | I25: 46477 | J25: PIKLT002 | K25: 172.17.12.116 | L25: DHCP | M25: ✓ | Y25: ACTIVE | Z25: CLARUS | AA25: 028/PO/HR&GA/GA/ I/2021 | AB25: LUSY | AC25: 0856-9576-1612 | AD25: PC DEPRE JAN 2021
A26: 22 | B26: FI-00607 | C26: LAPTOP | D26: FINANCE DIV | E26: FA | F26: IMAN KOESTIAMAN | G26: 1112021 | H26: 44286 | I26: 46477 | J26: PIKLT004 | K26: 172.17.12.186 | L26: DHCP | M26: ✓ | Y26: ACTIVE | Z26: CLARUS | AA26: 028/PO/HR&GA/GA/ I/2021 | AB26: LUSY | AC26: 0856-9576-1612 | AD26: PC DEPRE JAN 2021
A27: 23 | B27: FI-00612 | C27: WORKSTATION | D27: INJECTION MOLD DIV | E27: MOLD MAKING | F27: CATIA 2 (DADI HERIYANTO) | G27: 1709001 | H27: 44316 | I27: 46507 | J27: PIKPC156 | K27: 172.17.20.133 | L27: 172.17.218.7 | Q27: ✓ | Y27: ACTIVE | Z27: CLARUS | AA27: 021/PO/HR&GA/GA/ XII/2020 | AB27: LUSY | AC27: 0856-9576-1612 | AD27: PC DEPRE DES 2020
A28: 24 | B28: FI-00616 | C28: LAPTOP | D28: GENERAL AFFAIR DIV | E28: IT LEGAL | F28: KOITO M-08 (AYUNG) | G28: 1205001 | H28: 44377 | I28: 46568 | J28: - | K28: - | L28: DHCP | N28: ✓ | Y28: ACTIVE | Z28: CLARUS | AA28: 027/PO/HR&GA/GA/1/2021 | AB28: LUSY | AC28: 0856-9576-1612 | AD28: LAPTOP ADD JAN 2021
A29: 25 | B29: FI-00617 | C29: LAPTOP | D29: GENERAL AFFAIR DIV | E29: IT LEGAL | F29: KOITO M-09 (AYUNG) | G29: 1205001 | H29: 44377 | I29: 46568 | J29: PIKLT007 | K29: - | L29: DHCP | N29: ✓ | Y29: ACTIVE | Z29: CLARUS | AA29: 027/PO/HR&GA/GA/1/2021 | AB29: LUSY | AC29: 0856-9576-1612 | AD29: LAPTOP ADD JAN 2021
A30: 26 | B30: FI-00638 | C30: LAPTOP | D30: QA DIV | E30: QT | F30: HERMAN AZIS | G30: 1104009 | H30: 44406 | I30: 46808 | J30: PIKPC111 | K30: 172.17.12.133 | L30: DHCP | M30: ✓ | Y30: ACTIVE | Z30: SBTELECOM | AA30: 023/PO/HR&GA/GA/ VI/2021 | AB30: ASTRI | AC30: 0811-1067-925 | AD30: UPGRADE LAP MNGR JUNI 2021 (20 UNIT)
A31: 27 | B31: FI-00639 | C31: LAPTOP | D31: EXECUTIVE BOARD | E31: - | F31: MUTSUHIKO UCHIYAMA | G31: 1007001 | H31: 44406 | I31: 46808 | J31: PIKPC116 | K31: 172.17.12.16 | L31: DHCP | M31: ✓ | Y31: ACTIVE | Z31: SBTELECOM | AA31: 023/PO/HR&GA/GA/ VI/2021 | AB31: ASTRI | AC31: 0811-1067-925 | AD31: UPGRADE LAP MNGR JUNI 2021 (20 UNIT)
A32: 28 | B32: FI-00640 | C32: LAPTOP | D32: EXECUTIVE BOARD | E32: - | F32: SHIBATANI KANTO | G32: 110501 | H32: 44406 | I32: 46808 | J32: PIKPC106 | K32: 172.17.12.18 | L32: DHCP | M32: ✓ | Y32: ACTIVE | Z32: SBTELECOM | AA32: 023/PO/HR&GA/GA/ VI/2021 | AB32: ASTRI | AC32: 0811-1067-925 | AD32: UPGRADE LAP MNGR JUNI 2021 (20 UNIT)
A33: 29 | B33: FI-00641 | C33: LAPTOP | D33: EXECUTIVE BOARD | E33: - | F33: ERMA PURNAMA WIDA PANE | G33: 1008001 | H33: 44406 | I33: 46808 | J33: PIKPC107 | K33: 172.17.12.31 | L33: DHCP | M33: ✓ | Y33: ACTIVE | Z33: SBTELECOM | AA33: 023/PO/HR&GA/GA/ VI/2021 | AB33: ASTRI | AC33: 0811-1067-925 | AD33: UPGRADE LAP MNGR JUNI 2021 (20 UNIT)
A34: 30 | B34: FI-00642 | C34: LAPTOP | D34: PURCHASING DIV | E34: PURCHASING DIV | F34: YUSUKE FUJISAWA | G34: 2205002 | H34: 44406 | I34: 46808 | J34: PIKPC109 | K34: 172.17.12.22 | L34: DHCP | M34: ✓ | Y34: ACTIVE | Z34: SBTELECOM | AA34: 023/PO/HR&GA/GA/ VI/2021 | AB34: ASTRI | AC34: 0811-1067-925 | AD34: UPGRADE LAP MNGR JUNI 2021 (20 UNIT)
A35: 31 | B35: FI-00643 | C35: LAPTOP | D35: PPIC DIV | E35: PPIC DIV | F35: TAKEO FUKUSHIMA | G35: 2311019 | H35: 44406 | I35: 46808 | J35: PIK1COM175 | K35: 172.17.11.130 | L35: DHCP | M35: ✓ | Y35: ACTIVE | Z35: SBTELECOM | AA35: 023/PO/HR&GA/GA/ VI/2021 | AB35: ASTRI | AC35: 0811-1067-925 | AD35: UPGRADE LAP MNGR JUNI 2021 (20 UNIT)
A36: 32 | B36: FI-00644 | C36: LAPTOP | D36: QE DIV | E36: QE DIV | F36: KATSUMI MOCHIZUKI | G36: 2305002 | H36: 44406 | I36: 46808 | J36: PIKLT006 | K36: 172.17.12.27 | L36: DHCP | M36: ✓ | Y36: ACTIVE | Z36: SBTELECOM | AA36: 023/PO/HR&GA/GA/ VI/2021 | AB36: ASTRI | AC36: 0811-1067-925 | AD36: UPGRADE LAP MNGR JUNI 2021 (20 UNIT)
A37: 33 | B37: FI-00645 | C37: LAPTOP | D37: TECHNICAL DIV | E37: TECHNICAL DIV | F37: YUSUKE ADACHI | G37: 2305001 | H37: 44406 | I37: 46808 | J37: PIKPC101 | K37: 172.17.11.23 | L37: DHCP | M37: ✓ | Y37: ACTIVE | Z37: SBTELECOM | AA37: 023/PO/HR&GA/GA/ VI/2021 | AB37: ASTRI | AC37: 0811-1067-925 | AD37: UPGRADE LAP MNGR JUNI 2021 (20 UNIT)
A38: 34 | B38: FI-00646 | C38: LAPTOP | D38: TECHNICAL DIV | E38: M/C MAINTENANCE | F38: TEGUH MAHENDRA | G38: 1301030 | H38: 44406 | I38: 46808 | J38: PIKPC102 | K38: 172.17.11.73 | L38: DHCP | M38: ✓ | Y38: ACTIVE | Z38: SBTELECOM | AA38: 023/PO/HR&GA/GA/ VI/2021 | AB38: ASTRI | AC38: 0811-1067-925 | AD38: UPGRADE LAP MNGR JUNI 2021 (20 UNIT)
A39: 35 | B39: FI-00647 | C39: LAPTOP | D39: PART PROCESS DIV | E39: ASSEMBLING | F39: A ZAKY ALATTAS | G39: 1301005 | H39: 44406 | I39: 46808 | J39: PIKPC118 | K39: 172.17.11.66 | L39: DHCP | M39: ✓ | Y39: ACTIVE | Z39: SBTELECOM | AA39: 023/PO/HR&GA/GA/ VI/2021 | AB39: ASTRI | AC39: 0811-1067-925 | AD39: UPGRADE LAP MNGR JUNI 2021 (20 UNIT)
A40: 36 | B40: FI-00648 | C40: LAPTOP | D40: QA DIV | E40: QI | F40: SUKADI | G40: 1109118 | H40: 44406 | I40: 46808 | J40: PIKPC119 | K40: 172.17.12.165 | L40: DHCP | M40: ✓ | Y40: ACTIVE | Z40: SBTELECOM | AA40: 023/PO/HR&GA/GA/ VI/2021 | AB40: ASTRI | AC40: 0811-1067-925 | AD40: UPGRADE LAP MNGR JUNI 2021 (20 UNIT)
...

Sheet  LAMA CCTV
G1: LIST ASSET CCTV | Q1: INFORMASI PEMBELIAN
B2: Tanggal Update: | F2: =TODAY() -> 46122
B3: User | L3: Tahun
B4: NO | C4: ZONA | D4: ID | E4: NO.ASSET | F4: TYPE | G4: DIVISI | H4: DEPT | I4: NAMA | J4: HOSTNAME | K4: IP ADDRESS | L4: Pemberlian | M4: Batas Depresiasi (5 Tahun) | N4: Batas Extend (+1 Tahun) | O4: Status | P4: PLAN DISPOSE | Q4: SUPPLIER | R4: NO PO | S4: AKUISISI | T4: PIC SUPPLIER | U4: KONTAK SUPPLIER | V4: MODEL | W4: SERIAL NUMBER
B5: 1 | C5: ZONA 1 | D5: CAM-01 | E5: FI-00999 | F5: OUTDOOR | G5: GENERAL AFFAIR | H5: IT LEGAL DEPT | I5: PARKIR MOBIL 1 | J5: PIK1CAM001 | K5: 172.17.101.42 | L5: 2025 | M5: =L5+5 -> 2030 | N5: =M5+1 -> 2031 | O5: ACTIVE | P5: 47880 | Q5: PILAR TEKNOLOGI SOLUSI | R5: 027/PO/HR&GA/GA/V/2024 | S5: 45931 | T5: ARGAN | U5: 085711148741
B6: 2 | C6: ZONA 1 | D6: CAM-02 | E6: FI-01000 | F6: OUTDOOR | G6: GENERAL AFFAIR | H6: IT LEGAL DEPT | I6: LOBY LUAR | J6: PIK1CAM002 | K6: 172.17.101.14 | L6: 2025 | M6: =L6+5 -> 2030 | N6: =M6+1 -> 2031 | O6: ACTIVE | P6: 47880 | Q6: PILAR TEKNOLOGI SOLUSI | R6: 027/PO/HR&GA/GA/V/2024 | S6: 45931 | T6: ARGAN | U6: 085711148741
B7: 3 | C7: ZONA 1 | D7: CAM-03 | E7: FI-01009 | F7: OUTDOOR | G7: GENERAL AFFAIR | H7: IT LEGAL DEPT | I7: DEPAN POSKO | J7: PIK1CAM003 | K7: 172.17.101.10 | L7: 2025 | M7: =L7+5 -> 2030 | N7: =M7+1 -> 2031 | O7: ACTIVE | P7: 47908 | Q7: PILAR TEKNOLOGI SOLUSI | R7: 076/PO/HR&GA/GA/V/2024 | S7: 45962 | T7: ARGAN | U7: 085711148741
B8: 4 | C8: ZONA 1 | D8: CAM-04 | E8: FI-00188 | F8: OUTDOOR | G8: GENERAL AFFAIR | H8: IT LEGAL DEPT | I8: PARKIR MOBIL 2 | J8: PIK1CAM004 | K8: 172.17.101.32 | L8: 2014 | M8: =L8+5 -> 2019 | N8: =M8+1 -> 2020 | O8: ACTIVE | P8: 46235 | Q8: SECOM INDONESIA | R8: 22/HRGA/PO/IX/2014 | S8: 42004
B9: 5 | C9: ZONA 1 | D9: CAM-05 | E9: FI-00728 | F9: OUTDOOR | G9: GENERAL AFFAIR | H9: IT LEGAL DEPT | I9: PARKIR MOTOR | J9: PIK1CAM005 | K9: 172.17.101.11 | L9: 2023 | M9: =L9+5 -> 2028 | N9: =M9+1 -> 2029 | O9: ACTIVE | P9: 47119 | Q9: SECOM INDONESIA | R9: 069/PO/HR&GA/GA/XI/2022 | S9: 45044 | T9: CAHYO
B10: 6 | C10: ZONA 1 | D10: CAM-06 | E10: FI-01010 | F10: OUTDOOR | G10: GENERAL AFFAIR | H10: IT LEGAL DEPT | I10: PARKIR MOBIL 3 | J10: PIK1CAM006 | K10: 172.17.101.41 | L10: 2025 | M10: =L10+5 -> 2030 | N10: =M10+1 -> 2031 | O10: ACTIVE | P10: 47908 | Q10: PILAR TEKNOLOGI SOLUSI | R10: 076/PO/HR&GA/GA/V/2024 | S10: 45962 | T10: ARGAN | U10: 085711148741
B11: 7 | C11: ZONA 1 | D11: CAM-07 | E11: FI-01053 | F11: OUTDOOR | G11: GENERAL AFFAIR | H11: IT LEGAL DEPT | I11: TPS 1 | J11: PIK1CAM007 | K11: 172.17.101.13 | L11: 2025 | M11: =L11+5 -> 2030 | N11: =M11+1 -> 2031 | O11: ACTIVE | P11: 47939 | Q11: PILAR TEKNOLOGI SOLUSI | R11: 035/PO/HR&GA/GA/ VI/2024 | S11: 45748 | T11: ARGAN | U11: 085711148741
B12: 8 | C12: ZONA 1 | D12: CAM-08 | E12: FI-01054 | F12: OUTDOOR | G12: GENERAL AFFAIR | H12: IT LEGAL DEPT | I12: TENT HOUSE 2 (BOILEER BELAKANG) | J12: PIK1CAM008 | K12: 172.17.101.20 | L12: 2025 | M12: =L12+5 -> 2030 | N12: =M12+1 -> 2031 | O12: ACTIVE | P12: 47939 | Q12: PILAR TEKNOLOGI SOLUSI | R12: 035/PO/HR&GA/GA/ VI/2024 | S12: 45748 | T12: ARGAN | U12: 085711148741
B13: 9 | C13: ZONA 1 | D13: CAM-09 | E13: FI-01007 | F13: DOME | G13: GENERAL AFFAIR | H13: IT LEGAL DEPT | I13: LOBBY DALAM | J13: PIK1CAM009 | K13: 172.17.101.4 | L13: 2025 | M13: =L13+5 -> 2030 | N13: =M13+1 -> 2031 | O13: ACTIVE | P13: 47969 | Q13: PILAR TEKNOLOGI SOLUSI | R13: 039/PO/HR&GA/GA/VIII/2024 | S13: 45962 | T13: ARGAN | U13: 085711148741
B14: 10 | C14: ZONA 1 | D14: CAM-10 | E14: FI-01046 | F14: DOME | G14: GENERAL AFFAIR | H14: IT LEGAL DEPT | I14: LORONG PANTRY | J14: PIK1CAM010 | K14: 172.17.101.22 | L14: 2025 | M14: =L14+5 -> 2030 | N14: =M14+1 -> 2031 | O14: ACTIVE | P14: 47969 | Q14: PILAR TEKNOLOGI SOLUSI | R14: 006/PO/HR&GA/GA/XI/2024 | S14: 45689 | T14: ARGAN | U14: 085711148741
B15: 11 | C15: ZONA 1 | D15: CAM-11 | E15: FI-00991 | F15: DOME | G15: GENERAL AFFAIR | H15: IT LEGAL DEPT | I15: OFFICE ADM 1 | J15: PIK1CAM011 | K15: 172.17.101.31 | L15: 2024 | M15: =L15+5 -> 2029 | N15: =M15+1 -> 2030 | O15: ACTIVE | P15: 48000 | Q15: PILAR TEKNOLOGI SOLUSI | R15: 075/PO/HR&GA/GA/V/2024 | S15: 45536 | T15: ARGAN | U15: 085711148741
B16: 12 | C16: ZONA 1 | D16: CAM-12 | E16: FI-00992 | F16: DOME | G16: GENERAL AFFAIR | H16: IT LEGAL DEPT | I16: OFFICE ADM 2 | J16: PIK1CAM012 | K16: 172.17.101.5 | L16: =2024 -> 2024 | M16: =L16+5 -> 2029 | N16: =M16+1 -> 2030 | O16: ACTIVE | P16: 48000 | Q16: PILAR TEKNOLOGI SOLUSI | R16: 075/PO/HR&GA/GA/V/2024 | S16: 45536 | T16: ARGAN | U16: 085711148741
B17: 13 | C17: ZONA 1 | D17: CAM-13 | E17: FI-00993 | F17: DOME | G17: GENERAL AFFAIR | H17: IT LEGAL DEPT | I17: SERVER ROOM | J17: PIK1CAM013 | K17: 172.17.11.43 | L17: =2024 -> 2024 | M17: =L17+5 -> 2029 | N17: =M17+1 -> 2030 | O17: ACTIVE | P17: 48030 | Q17: PILAR TEKNOLOGI SOLUSI | R17: 075/PO/HR&GA/GA/V/2024 | S17: 45536 | T17: ARGAN | U17: 085711148741
B18: 14 | C18: ZONA 1 | D18: CAM-14 | E18: FI-01027 | F18: DOME | G18: GENERAL AFFAIR | H18: IT LEGAL DEPT | I18: LORONG OFFICE 1 | J18: PIK1CAM014 | K18: 172.17.101.19 | L18: 2025 | M18: =L18+5 -> 2030 | N18: =M18+1 -> 2031 | O18: ACTIVE | P18: 48030 | Q18: PILAR TEKNOLOGI SOLUSI | R18: 065/PO/HR&GA/GA/IX/2024 | S18: 45658 | T18: ARGAN | U18: 085711148741
B19: 15 | C19: ZONA 1 | D19: CAM-15 | E19: BELUM AKUSISI | F19: OUTDOOR | G19: GENERAL AFFAIR | H19: IT LEGAL DEPT | I19: FINISH GOOD | J19: PIK1CAM015 | K19: 172.17.101.17 | L19: 2025 | M19: =L19+5 -> 2030 | N19: =M19+1 -> 2031 | O19: ACTIVE | P19: 45809 | Q19: PILAR TEKNOLOGI SOLUSI | R19: 072/PO/HR&GA/GA/VI/2025 | T19: ARGAN | U19: 085711148741 | V19: WV-S1136A | W19: YHV18108
B20: 16 | C20: ZONA 1 | D20: CAM-16 | E20: FI-01028 | F20: DOME | G20: GENERAL AFFAIR | H20: IT LEGAL DEPT | I20: OFFICE PROD | J20: PIK1CAM016 | K20: 172.17.101.21 | L20: 2025 | M20: =L20+5 -> 2030 | N20: =M20+1 -> 2031 | O20: ACTIVE | P20: 48061 | Q20: PILAR TEKNOLOGI SOLUSI | R20: 065/PO/HR&GA/GA/IX/2024 | S20: 45658 | T20: ARGAN | U20: 085711148741
B21: 17 | C21: ZONA 1 | D21: CAM-17 | E21: FI-00114 | F21: DOME | G21: GENERAL AFFAIR | H21: IT LEGAL DEPT | I21: TEST ROOM | J21: PIK1CAM017 | K21: 172.17.101.26 | L21: 2012 | M21: =L21+5 -> 2017 | N21: =M21+1 -> 2018 | O21: ACTIVE | P21: 46113 | Q21: SECOM INDOPRATAMA | R21: 010/GA/XII/2010REV | S21: 41000
B22: 18 | C22: ZONA 1 | D22: CAM-18 | E22: BELUM AKUSISI | F22: OUTDOOR | G22: GENERAL AFFAIR | H22: IT LEGAL DEPT | I22: AREA MTC | J22: PIK1CAM018 | K22: 172.17.101.12 | L22: 2025 | M22: =L22+5 -> 2030 | N22: =M22+1 -> 2031 | O22: ACTIVE | P22: 45748 | Q22: PILAR TEKNOLOGI SOLUSI | R22: 010/PO/HR&GA/GA/VI/2025 | T22: ARGAN | U22: 085711148741 | V22: WV-S1136A | W22: YHV8154
B23: 19 | C23: ZONA 1 | D23: CAM-19 | E23: FI-00114 | F23: OUTDOOR | G23: GENERAL AFFAIR | H23: IT LEGAL DEPT | I23: LORONG MEZANINE | J23: PIK1CAM019 | K23: 172.17.101.35 | L23: 2012 | M23: =L23+5 -> 2017 | N23: =M23+1 -> 2018 | O23: ACTIVE | P23: 46113 | Q23: SECOM INDOPRATAMA | R23: 010/GA/XII/2010REV | S23: 41000 | V23: WV-SP305
B24: 20 | C24: ZONA 1 | D24: CAM-20 | E24: FI-00114 | F24: OUTDOOR | G24: GENERAL AFFAIR | H24: IT LEGAL DEPT | I24: MEZANI STORE | J24: PIK1CAM020 | K24: 172.17.101.36 | L24: 2012 | M24: =L24+5 -> 2017 | N24: =M24+1 -> 2018 | O24: ACTIVE | P24: 46082 | Q24: SECOM INDOPRATAMA | R24: 010/GA/XII/2010REV | S24: 41000 | V24: WV-SP305
B25: 21 | C25: ZONA 1 | D25: CAM-21 | E25: FI-00114 | F25: OUTDOOR | G25: GENERAL AFFAIR | H25: IT LEGAL DEPT | I25: MEZANI LIFT | J25: PIK1CAM021 | K25: 172.17.101.33 | L25: 2012 | M25: =L25+5 -> 2017 | N25: =M25+1 -> 2018 | O25: ACTIVE | P25: 46143 | Q25: SECOM INDOPRATAMA | R25: 010/GA/XII/2010REV | S25: 41000 | V25: WV-SP305
B26: 22 | C26: ZONA 1 | D26: CAM-22 | E26: FI-00114 | F26: OUTDOOR | G26: GENERAL AFFAIR | H26: IT LEGAL DEPT | I26: INJ MULTI COLOR | J26: PIK1CAM022 | K26: 172.17.101.25 | L26: 2012 | M26: =L26+5 -> 2017 | N26: =M26+1 -> 2018 | O26: ACTIVE | P26: 46143 | Q26: SECOM INDOPRATAMA | R26: 010/GA/XII/2010REV | S26: 41000 | V26: WV-SP305
B27: 23 | C27: ZONA 1 | D27: CAM-23 | E27: FI-00114 | F27: OUTDOOR | G27: GENERAL AFFAIR | H27: IT LEGAL DEPT | I27: INJECTION LENSA | J27: PIK1CAM023 | K27: 172.17.101.24 | L27: 2012 | M27: =L27+5 -> 2017 | N27: =M27+1 -> 2018 | O27: ACTIVE | P27: 46174 | Q27: SECOM INDOPRATAMA | R27: 010/GA/XII/2010REV | S27: 41000 | V27: WV-SP305
B28: 24 | C28: ZONA 1 | D28: CAM-24 | E28: BELUM AKUSISI | F28: OUTDOOR | G28: GENERAL AFFAIR | H28: IT LEGAL DEPT | I28: INJECT BMC | J28: PIK1CAM024 | K28: 172.17.101.40 | L28: 2025 | M28: =L28+5 -> 2030 | N28: =M28+1 -> 2031 | O28: ACTIVE | P28: 45809 | Q28: PILAR TEKNOLOGI SOLUSI | R28: 072/PO/HR&GA/GA/VI/2025 | T28: ARGAN | U28: 085711148741 | V28: WV-S1136A | W28: YHV18109
B29: 25 | C29: ZONA 1 | D29: CAM-25 | E29: FI-00333 | F29: OUTDOOR | G29: GENERAL AFFAIR | H29: IT LEGAL DEPT | I29: MATERIAL RESIN 1 | J29: PIK1CAM025 | K29: 172.17.101.27 | L29: 2016 | M29: =L29+5 -> 2021 | N29: =M29+1 -> 2022 | O29: ACTIVE | P29: 46235
B30: 26 | C30: ZONA 1 | D30: CAM-26 | E30: FI-01045 | F30: DOME | G30: GENERAL AFFAIR | H30: IT LEGAL DEPT | I30: MATERIAL RESIN 2 | J30: PIK1CAM026 | K30: 172.17.101.6 | L30: 2025 | M30: =L30+5 -> 2030 | N30: =M30+1 -> 2031 | O30: ACTIVE | P30: 48061 | Q30: PILAR TEKNOLOGI SOLUSI | R30: 020/PO/HR&GA/GA/XI/2024 | S30: 45689 | T30: ARGAN | U30: 085711148741
B31: 27 | C31: ZONA 1 | D31: CAM-27 | E31: FI-00114 | F31: OUTDOOR | G31: GENERAL AFFAIR | H31: IT LEGAL DEPT | I31: PART STORE | J31: PIK1CAM027 | K31: 172.17.101.7 | L31: 2012 | M31: =L31+5 -> 2017 | N31: =M31+1 -> 2018 | O31: ACTIVE | P31: 46054 | Q31: SECOM INDOPRATAMA | R31: 010/GA/XII/2010REV | S31: 41000 | V31: WV-SP305
B32: 28 | C32: ZONA 1 | D32: CAM-28 | E32: FI-00184 | F32: OUTDOOR | G32: GENERAL AFFAIR | H32: IT LEGAL DEPT | I32: LOADING 1 | J32: PIK1CAM028 | K32: 172.17.101.18 | L32: 2014 | M32: =L32+5 -> 2019 | N32: =M32+1 -> 2020 | O32: ACTIVE | P32: 46082 | Q32: SECOM INDONESIA | R32: 22/HRGA/PO/IX/2014 | S32: 42004
B33: 29 | C33: ZONA 1 | D33: CAM-29 | E33: FI-00185 | F33: OUTDOOR | G33: GENERAL AFFAIR | H33: IT LEGAL DEPT | I33: LOADING 2 | J33: PIK1CAM029 | K33: 172.17.101.23 | L33: 2014 | M33: =L33+5 -> 2019 | N33: =M33+1 -> 2020 | O33: ACTIVE | P33: 45901 | Q33: SECOM INDONESIA | R33: 22/HRGA/PO/IX/2014 | S33: 42004
B34: 30 | C34: ZONA 1 | D34: CAM-30 | E34: FI-00186 | F34: OUTDOOR | G34: GENERAL AFFAIR | H34: IT LEGAL DEPT | I34: LOADING 3 | J34: PIK1CAM030 | K34: 172.17.101.30 | L34: 2014 | M34: =L34+5 -> 2019 | N34: =M34+1 -> 2020 | O34: ACTIVE | P34: 45931 | Q34: SECOM INDONESIA | R34: 22/HRGA/PO/IX/2014 | S34: 42004
B35: 31 | C35: ZONA 1 | D35: CAM-31 | E35: FI-00111 | F35: OUTDOOR | G35: GENERAL AFFAIR | H35: IT LEGAL DEPT | I35: INCOME STORE | J35: PIK1CAM031 | K35: 172.17.101.9 | L35: 2012 | M35: =L35+5 -> 2017 | N35: =M35+1 -> 2018 | O35: ACTIVE | P35: 46174 | Q35: SECOM INDOPRATAMA | R35: 010/GA/XII/2010REV | S35: 41000 | V35: WV-SF335
B36: 32 | C36: ZONA 1 | D36: CAM-32 | E36: FI-00923 | F36: DOME | G36: GENERAL AFFAIR | H36: IT LEGAL DEPT | I36: OFFICE QLTY1 | J36: PIK1CAM032 | K36: 172.17.101.65 | L36: 2023 | M36: =L36+5 -> 2028 | N36: =M36+1 -> 2029 | O36: ACTIVE | P36: 47119 | Q36: SECOM INDONESIA | R36: 026/PO/HR&GA/GA/IX/2023 | S36: 45289 | T36: CAHYO | V36: WV-U2130L
B37: 33 | C37: ZONA 1 | D37: CAM-33 | E37: FI-01047 | F37: DOME | G37: GENERAL AFFAIR | H37: IT LEGAL DEPT | I37: OFFICE QLTY2 | J37: PIK1CAM033 | K37: 172.17.101.64 | L37: 2025 | M37: =L37+5 -> 2030 | N37: =M37+1 -> 2031 | O37: ACTIVE | P37: 48092 | Q37: PILAR TEKNOLOGI SOLUSI | R37: 006/PO/HR&GA/GA/XI/2024 | S37: 45689 | T37: ARGAN | U37: 085711148741
B38: 34 | C38: ZONA 1 | D38: CAM-34 | E38: FI-01008 | F38: DOME | G38: GENERAL AFFAIR | H38: IT LEGAL DEPT | I38: LORONG QLTY | J38: PIK1CAM034 | K38: 172.17.101.63 | L38: 2025 | M38: =L38+5 -> 2030 | N38: =M38+1 -> 2031 | O38: ACTIVE | P38: 48092 | Q38: PILAR TEKNOLOGI SOLUSI | R38: 039/PO/HR&GA/GA/VIII/2024 | S38: 45962 | T38: ARGAN | U38: 085711148741
B39: 35 | C39: ZONA 1 | D39: CAM-35 | E39: BELUM AKUSISI | F39: OUTDOOR | G39: GENERAL AFFAIR | H39: IT LEGAL DEPT | I39: VIBRASI ROOM | J39: PIK1CAM035 | K39: 172.17.101.44 | L39: 2025 | M39: =L39+5 -> 2030 | N39: =M39+1 -> 2031 | O39: ACTIVE | P39: 45778 | Q39: PILAR TEKNOLOGI SOLUSI | R39: 010/PO/HR&GA/GA/VI/2025 | T39: ARGAN | U39: 085711148741 | V39: WV-S1136A | W39: YHV18105
B40: 36 | C40: ZONA 1 | D40: CAM-36 | E40: FI-01078 | F40: DOME | G40: GENERAL AFFAIR | H40: IT LEGAL DEPT | I40: SERVER ROOM2 | J40: PIK1CAM036 | K40: 172.17.101.50 | L40: 2025 | M40: =L40+5 -> 2030 | N40: =M40+1 -> 2031 | O40: ACTIVE | P40: 48122 | Q40: PILAR TEKNOLOGI SOLUSI | R40: 038/PO/HR&GA/GA/VII/2024 | S40: 45778 | T40: ARGAN | U40: 085711148741
...

Sheet CCTV2026-ori
B1: CCTV CAMERA ASSET LIST
B2: NO URUT | C2: NO CAM | D2: NO.ASSET | E2: TYPE | H2: NAMA | K2: IP ADDRESS MAIN | L2: IP ADDRESS BACKUP | M2: Tahun | P2: Status | Q2: AREA | R2: LISENSI | S2: Windows | T2: Trend Micro (Max PC & Svr 265) | U2: Cybereason (Max PC & Svr 245) | AC2: Plan mapping depresiasi | AD2: 2026 | AM2: 2027 | AY2: 2028 | BK2: 2029 | BW2: 2030
